[2023.08.07 21:38:09] E Task exception was never retrieved
future: <Task finished name='Task-1' coro=<make_schedule() done, defined at /Users/ilyasleptsov/Desktop/python/dex_gainers_losers/send_top_gainers_losers.py:8> exception=TypeError("__init__() got an unexpected keyword argument 'hours'")>
Traceback (most recent call last):
  File "/Users/ilyasleptsov/Desktop/python/dex_gainers_losers/send_top_gainers_losers.py", line 10, in make_schedule
    scheduler.add_job(send_daily_stats, 'cron', hours=22)
  File "/Users/ilyasleptsov/Library/Caches/pypoetry/virtualenvs/dex-gainers-losers-bKWl_PyR-py3.9/lib/python3.9/site-packages/apscheduler/schedulers/base.py", line 424, in add_job
    'trigger': self._create_trigger(trigger, trigger_args),
  File "/Users/ilyasleptsov/Library/Caches/pypoetry/virtualenvs/dex-gainers-losers-bKWl_PyR-py3.9/lib/python3.9/site-packages/apscheduler/schedulers/base.py", line 925, in _create_trigger
    return self._create_plugin_instance('trigger', trigger, trigger_args)
  File "/Users/ilyasleptsov/Library/Caches/pypoetry/virtualenvs/dex-gainers-losers-bKWl_PyR-py3.9/lib/python3.9/site-packages/apscheduler/schedulers/base.py", line 910, in _create_plugin_instance
    return plugin_cls(**constructor_kwargs)
TypeError: __init__() got an unexpected keyword argument 'hours'
[2023.08.07 21:38:09] W PyNaCl is not installed, voice will NOT be supported
[2023.08.07 21:40:08] W PyNaCl is not installed, voice will NOT be supported
[2023.08.08 00:24:17] W PyNaCl is not installed, voice will NOT be supported
[2023.08.08 00:25:02] E Task exception was never retrieved
future: <Task finished name='Task-1' coro=<make_schedule() done, defined at /Users/ilyasleptsov/Desktop/python/dex_gainers_losers/send_top_gainers_losers.py:8> exception=TypeError("__init__() got an unexpected keyword argument 'hours'")>
Traceback (most recent call last):
  File "/Users/ilyasleptsov/Desktop/python/dex_gainers_losers/send_top_gainers_losers.py", line 10, in make_schedule
    scheduler.add_job(send_daily_stats, 'cron', hours="22")
  File "/Users/ilyasleptsov/Library/Caches/pypoetry/virtualenvs/dex-gainers-losers-bKWl_PyR-py3.9/lib/python3.9/site-packages/apscheduler/schedulers/base.py", line 424, in add_job
    'trigger': self._create_trigger(trigger, trigger_args),
  File "/Users/ilyasleptsov/Library/Caches/pypoetry/virtualenvs/dex-gainers-losers-bKWl_PyR-py3.9/lib/python3.9/site-packages/apscheduler/schedulers/base.py", line 925, in _create_trigger
    return self._create_plugin_instance('trigger', trigger, trigger_args)
  File "/Users/ilyasleptsov/Library/Caches/pypoetry/virtualenvs/dex-gainers-losers-bKWl_PyR-py3.9/lib/python3.9/site-packages/apscheduler/schedulers/base.py", line 910, in _create_plugin_instance
    return plugin_cls(**constructor_kwargs)
TypeError: __init__() got an unexpected keyword argument 'hours'
[2023.08.08 00:25:02] W PyNaCl is not installed, voice will NOT be supported
[2023.08.08 00:29:38] E Attempting a reconnect in 1.38s
Traceback (most recent call last):
  File "/Users/ilyasleptsov/Library/Caches/pypoetry/virtualenvs/dex-gainers-losers-bKWl_PyR-py3.9/lib/python3.9/site-packages/discord/client.py", line 659, in connect
    await self.ws.poll_event()
  File "/Users/ilyasleptsov/Library/Caches/pypoetry/virtualenvs/dex-gainers-losers-bKWl_PyR-py3.9/lib/python3.9/site-packages/discord/gateway.py", line 646, in poll_event
    raise ConnectionClosed(self.socket, shard_id=self.shard_id, code=code) from None
discord.errors.ConnectionClosed: Shard ID None WebSocket closed with 1000
[2023.08.08 04:56:45] E Attempting a reconnect in 0.19s
Traceback (most recent call last):
  File "/Users/ilyasleptsov/Library/Caches/pypoetry/virtualenvs/dex-gainers-losers-bKWl_PyR-py3.9/lib/python3.9/site-packages/aiohttp/connector.py", line 1155, in _create_direct_connection
    hosts = await asyncio.shield(host_resolved)
  File "/Users/ilyasleptsov/Library/Caches/pypoetry/virtualenvs/dex-gainers-losers-bKWl_PyR-py3.9/lib/python3.9/site-packages/aiohttp/connector.py", line 874, in _resolve_host
    addrs = await self._resolver.resolve(host, port, family=self._family)
  File "/Users/ilyasleptsov/Library/Caches/pypoetry/virtualenvs/dex-gainers-losers-bKWl_PyR-py3.9/lib/python3.9/site-packages/aiohttp/resolver.py", line 33, in resolve
    infos = await self._loop.getaddrinfo(
  File "/Library/Developer/CommandLineTools/Library/Frameworks/Python3.framework/Versions/3.9/lib/python3.9/asyncio/base_events.py", line 856, in getaddrinfo
    return await self.run_in_executor(
  File "/Library/Developer/CommandLineTools/Library/Frameworks/Python3.framework/Versions/3.9/lib/python3.9/concurrent/futures/thread.py", line 52, in run
    result = self.fn(*self.args, **self.kwargs)
  File "/Library/Developer/CommandLineTools/Library/Frameworks/Python3.framework/Versions/3.9/lib/python3.9/socket.py", line 953, in getaddrinfo
    for res in _socket.getaddrinfo(host, port, family, type, proto, flags):
socket.gaierror: [Errno 8] nodename nor servname provided, or not known

The above exception was the direct cause of the following exception:

Traceback (most recent call last):
  File "/Users/ilyasleptsov/Library/Caches/pypoetry/virtualenvs/dex-gainers-losers-bKWl_PyR-py3.9/lib/python3.9/site-packages/discord/client.py", line 656, in connect
    self.ws = await asyncio.wait_for(coro, timeout=60.0)
  File "/Library/Developer/CommandLineTools/Library/Frameworks/Python3.framework/Versions/3.9/lib/python3.9/asyncio/tasks.py", line 481, in wait_for
    return fut.result()
  File "/Users/ilyasleptsov/Library/Caches/pypoetry/virtualenvs/dex-gainers-losers-bKWl_PyR-py3.9/lib/python3.9/site-packages/discord/gateway.py", line 372, in from_client
    socket = await client.http.ws_connect(str(url))
  File "/Users/ilyasleptsov/Library/Caches/pypoetry/virtualenvs/dex-gainers-losers-bKWl_PyR-py3.9/lib/python3.9/site-packages/discord/http.py", line 537, in ws_connect
    return await self.__session.ws_connect(url, **kwargs)
  File "/Users/ilyasleptsov/Library/Caches/pypoetry/virtualenvs/dex-gainers-losers-bKWl_PyR-py3.9/lib/python3.9/site-packages/aiohttp/client.py", line 779, in _ws_connect
    resp = await self.request(
  File "/Users/ilyasleptsov/Library/Caches/pypoetry/virtualenvs/dex-gainers-losers-bKWl_PyR-py3.9/lib/python3.9/site-packages/aiohttp/client.py", line 536, in _request
    conn = await self._connector.connect(
  File "/Users/ilyasleptsov/Library/Caches/pypoetry/virtualenvs/dex-gainers-losers-bKWl_PyR-py3.9/lib/python3.9/site-packages/aiohttp/connector.py", line 540, in connect
    proto = await self._create_connection(req, traces, timeout)
  File "/Users/ilyasleptsov/Library/Caches/pypoetry/virtualenvs/dex-gainers-losers-bKWl_PyR-py3.9/lib/python3.9/site-packages/aiohttp/connector.py", line 901, in _create_connection
    _, proto = await self._create_direct_connection(req, traces, timeout)
  File "/Users/ilyasleptsov/Library/Caches/pypoetry/virtualenvs/dex-gainers-losers-bKWl_PyR-py3.9/lib/python3.9/site-packages/aiohttp/connector.py", line 1169, in _create_direct_connection
    raise ClientConnectorError(req.connection_key, exc) from exc
aiohttp.client_exceptions.ClientConnectorError: Cannot connect to host gateway-us-east1-b.discord.gg:443 ssl:default [nodename nor servname provided, or not known]
[2023.08.08 04:56:50] E Attempting a reconnect in 0.04s
Traceback (most recent call last):
  File "/Users/ilyasleptsov/Library/Caches/pypoetry/virtualenvs/dex-gainers-losers-bKWl_PyR-py3.9/lib/python3.9/site-packages/aiohttp/connector.py", line 1155, in _create_direct_connection
    hosts = await asyncio.shield(host_resolved)
  File "/Users/ilyasleptsov/Library/Caches/pypoetry/virtualenvs/dex-gainers-losers-bKWl_PyR-py3.9/lib/python3.9/site-packages/aiohttp/connector.py", line 874, in _resolve_host
    addrs = await self._resolver.resolve(host, port, family=self._family)
  File "/Users/ilyasleptsov/Library/Caches/pypoetry/virtualenvs/dex-gainers-losers-bKWl_PyR-py3.9/lib/python3.9/site-packages/aiohttp/resolver.py", line 33, in resolve
    infos = await self._loop.getaddrinfo(
  File "/Library/Developer/CommandLineTools/Library/Frameworks/Python3.framework/Versions/3.9/lib/python3.9/asyncio/base_events.py", line 856, in getaddrinfo
    return await self.run_in_executor(
  File "/Library/Developer/CommandLineTools/Library/Frameworks/Python3.framework/Versions/3.9/lib/python3.9/concurrent/futures/thread.py", line 52, in run
    result = self.fn(*self.args, **self.kwargs)
  File "/Library/Developer/CommandLineTools/Library/Frameworks/Python3.framework/Versions/3.9/lib/python3.9/socket.py", line 953, in getaddrinfo
    for res in _socket.getaddrinfo(host, port, family, type, proto, flags):
socket.gaierror: [Errno 8] nodename nor servname provided, or not known

The above exception was the direct cause of the following exception:

Traceback (most recent call last):
  File "/Users/ilyasleptsov/Library/Caches/pypoetry/virtualenvs/dex-gainers-losers-bKWl_PyR-py3.9/lib/python3.9/site-packages/discord/client.py", line 656, in connect
    self.ws = await asyncio.wait_for(coro, timeout=60.0)
  File "/Library/Developer/CommandLineTools/Library/Frameworks/Python3.framework/Versions/3.9/lib/python3.9/asyncio/tasks.py", line 481, in wait_for
    return fut.result()
  File "/Users/ilyasleptsov/Library/Caches/pypoetry/virtualenvs/dex-gainers-losers-bKWl_PyR-py3.9/lib/python3.9/site-packages/discord/gateway.py", line 372, in from_client
    socket = await client.http.ws_connect(str(url))
  File "/Users/ilyasleptsov/Library/Caches/pypoetry/virtualenvs/dex-gainers-losers-bKWl_PyR-py3.9/lib/python3.9/site-packages/discord/http.py", line 537, in ws_connect
    return await self.__session.ws_connect(url, **kwargs)
  File "/Users/ilyasleptsov/Library/Caches/pypoetry/virtualenvs/dex-gainers-losers-bKWl_PyR-py3.9/lib/python3.9/site-packages/aiohttp/client.py", line 779, in _ws_connect
    resp = await self.request(
  File "/Users/ilyasleptsov/Library/Caches/pypoetry/virtualenvs/dex-gainers-losers-bKWl_PyR-py3.9/lib/python3.9/site-packages/aiohttp/client.py", line 536, in _request
    conn = await self._connector.connect(
  File "/Users/ilyasleptsov/Library/Caches/pypoetry/virtualenvs/dex-gainers-losers-bKWl_PyR-py3.9/lib/python3.9/site-packages/aiohttp/connector.py", line 540, in connect
    proto = await self._create_connection(req, traces, timeout)
  File "/Users/ilyasleptsov/Library/Caches/pypoetry/virtualenvs/dex-gainers-losers-bKWl_PyR-py3.9/lib/python3.9/site-packages/aiohttp/connector.py", line 901, in _create_connection
    _, proto = await self._create_direct_connection(req, traces, timeout)
  File "/Users/ilyasleptsov/Library/Caches/pypoetry/virtualenvs/dex-gainers-losers-bKWl_PyR-py3.9/lib/python3.9/site-packages/aiohttp/connector.py", line 1169, in _create_direct_connection
    raise ClientConnectorError(req.connection_key, exc) from exc
aiohttp.client_exceptions.ClientConnectorError: Cannot connect to host gateway-us-east1-b.discord.gg:443 ssl:default [nodename nor servname provided, or not known]
[2023.08.08 04:56:50] E Attempting a reconnect in 14.75s
Traceback (most recent call last):
  File "/Users/ilyasleptsov/Library/Caches/pypoetry/virtualenvs/dex-gainers-losers-bKWl_PyR-py3.9/lib/python3.9/site-packages/aiohttp/connector.py", line 1155, in _create_direct_connection
    hosts = await asyncio.shield(host_resolved)
  File "/Users/ilyasleptsov/Library/Caches/pypoetry/virtualenvs/dex-gainers-losers-bKWl_PyR-py3.9/lib/python3.9/site-packages/aiohttp/connector.py", line 874, in _resolve_host
    addrs = await self._resolver.resolve(host, port, family=self._family)
  File "/Users/ilyasleptsov/Library/Caches/pypoetry/virtualenvs/dex-gainers-losers-bKWl_PyR-py3.9/lib/python3.9/site-packages/aiohttp/resolver.py", line 33, in resolve
    infos = await self._loop.getaddrinfo(
  File "/Library/Developer/CommandLineTools/Library/Frameworks/Python3.framework/Versions/3.9/lib/python3.9/asyncio/base_events.py", line 856, in getaddrinfo
    return await self.run_in_executor(
  File "/Library/Developer/CommandLineTools/Library/Frameworks/Python3.framework/Versions/3.9/lib/python3.9/concurrent/futures/thread.py", line 52, in run
    result = self.fn(*self.args, **self.kwargs)
  File "/Library/Developer/CommandLineTools/Library/Frameworks/Python3.framework/Versions/3.9/lib/python3.9/socket.py", line 953, in getaddrinfo
    for res in _socket.getaddrinfo(host, port, family, type, proto, flags):
socket.gaierror: [Errno 8] nodename nor servname provided, or not known

The above exception was the direct cause of the following exception:

Traceback (most recent call last):
  File "/Users/ilyasleptsov/Library/Caches/pypoetry/virtualenvs/dex-gainers-losers-bKWl_PyR-py3.9/lib/python3.9/site-packages/discord/client.py", line 656, in connect
    self.ws = await asyncio.wait_for(coro, timeout=60.0)
  File "/Library/Developer/CommandLineTools/Library/Frameworks/Python3.framework/Versions/3.9/lib/python3.9/asyncio/tasks.py", line 481, in wait_for
    return fut.result()
  File "/Users/ilyasleptsov/Library/Caches/pypoetry/virtualenvs/dex-gainers-losers-bKWl_PyR-py3.9/lib/python3.9/site-packages/discord/gateway.py", line 372, in from_client
    socket = await client.http.ws_connect(str(url))
  File "/Users/ilyasleptsov/Library/Caches/pypoetry/virtualenvs/dex-gainers-losers-bKWl_PyR-py3.9/lib/python3.9/site-packages/discord/http.py", line 537, in ws_connect
    return await self.__session.ws_connect(url, **kwargs)
  File "/Users/ilyasleptsov/Library/Caches/pypoetry/virtualenvs/dex-gainers-losers-bKWl_PyR-py3.9/lib/python3.9/site-packages/aiohttp/client.py", line 779, in _ws_connect
    resp = await self.request(
  File "/Users/ilyasleptsov/Library/Caches/pypoetry/virtualenvs/dex-gainers-losers-bKWl_PyR-py3.9/lib/python3.9/site-packages/aiohttp/client.py", line 536, in _request
    conn = await self._connector.connect(
  File "/Users/ilyasleptsov/Library/Caches/pypoetry/virtualenvs/dex-gainers-losers-bKWl_PyR-py3.9/lib/python3.9/site-packages/aiohttp/connector.py", line 540, in connect
    proto = await self._create_connection(req, traces, timeout)
  File "/Users/ilyasleptsov/Library/Caches/pypoetry/virtualenvs/dex-gainers-losers-bKWl_PyR-py3.9/lib/python3.9/site-packages/aiohttp/connector.py", line 901, in _create_connection
    _, proto = await self._create_direct_connection(req, traces, timeout)
  File "/Users/ilyasleptsov/Library/Caches/pypoetry/virtualenvs/dex-gainers-losers-bKWl_PyR-py3.9/lib/python3.9/site-packages/aiohttp/connector.py", line 1169, in _create_direct_connection
    raise ClientConnectorError(req.connection_key, exc) from exc
aiohttp.client_exceptions.ClientConnectorError: Cannot connect to host gateway-us-east1-b.discord.gg:443 ssl:default [nodename nor servname provided, or not known]
[2023.08.08 09:00:27] E Attempting a reconnect in 7.32s
Traceback (most recent call last):
  File "/Users/ilyasleptsov/Library/Caches/pypoetry/virtualenvs/dex-gainers-losers-bKWl_PyR-py3.9/lib/python3.9/site-packages/aiohttp/connector.py", line 1155, in _create_direct_connection
    hosts = await asyncio.shield(host_resolved)
  File "/Users/ilyasleptsov/Library/Caches/pypoetry/virtualenvs/dex-gainers-losers-bKWl_PyR-py3.9/lib/python3.9/site-packages/aiohttp/connector.py", line 874, in _resolve_host
    addrs = await self._resolver.resolve(host, port, family=self._family)
  File "/Users/ilyasleptsov/Library/Caches/pypoetry/virtualenvs/dex-gainers-losers-bKWl_PyR-py3.9/lib/python3.9/site-packages/aiohttp/resolver.py", line 33, in resolve
    infos = await self._loop.getaddrinfo(
  File "/Library/Developer/CommandLineTools/Library/Frameworks/Python3.framework/Versions/3.9/lib/python3.9/asyncio/base_events.py", line 856, in getaddrinfo
    return await self.run_in_executor(
  File "/Library/Developer/CommandLineTools/Library/Frameworks/Python3.framework/Versions/3.9/lib/python3.9/concurrent/futures/thread.py", line 52, in run
    result = self.fn(*self.args, **self.kwargs)
  File "/Library/Developer/CommandLineTools/Library/Frameworks/Python3.framework/Versions/3.9/lib/python3.9/socket.py", line 953, in getaddrinfo
    for res in _socket.getaddrinfo(host, port, family, type, proto, flags):
socket.gaierror: [Errno 8] nodename nor servname provided, or not known

The above exception was the direct cause of the following exception:

Traceback (most recent call last):
  File "/Users/ilyasleptsov/Library/Caches/pypoetry/virtualenvs/dex-gainers-losers-bKWl_PyR-py3.9/lib/python3.9/site-packages/discord/client.py", line 656, in connect
    self.ws = await asyncio.wait_for(coro, timeout=60.0)
  File "/Library/Developer/CommandLineTools/Library/Frameworks/Python3.framework/Versions/3.9/lib/python3.9/asyncio/tasks.py", line 481, in wait_for
    return fut.result()
  File "/Users/ilyasleptsov/Library/Caches/pypoetry/virtualenvs/dex-gainers-losers-bKWl_PyR-py3.9/lib/python3.9/site-packages/discord/gateway.py", line 372, in from_client
    socket = await client.http.ws_connect(str(url))
  File "/Users/ilyasleptsov/Library/Caches/pypoetry/virtualenvs/dex-gainers-losers-bKWl_PyR-py3.9/lib/python3.9/site-packages/discord/http.py", line 537, in ws_connect
    return await self.__session.ws_connect(url, **kwargs)
  File "/Users/ilyasleptsov/Library/Caches/pypoetry/virtualenvs/dex-gainers-losers-bKWl_PyR-py3.9/lib/python3.9/site-packages/aiohttp/client.py", line 779, in _ws_connect
    resp = await self.request(
  File "/Users/ilyasleptsov/Library/Caches/pypoetry/virtualenvs/dex-gainers-losers-bKWl_PyR-py3.9/lib/python3.9/site-packages/aiohttp/client.py", line 536, in _request
    conn = await self._connector.connect(
  File "/Users/ilyasleptsov/Library/Caches/pypoetry/virtualenvs/dex-gainers-losers-bKWl_PyR-py3.9/lib/python3.9/site-packages/aiohttp/connector.py", line 540, in connect
    proto = await self._create_connection(req, traces, timeout)
  File "/Users/ilyasleptsov/Library/Caches/pypoetry/virtualenvs/dex-gainers-losers-bKWl_PyR-py3.9/lib/python3.9/site-packages/aiohttp/connector.py", line 901, in _create_connection
    _, proto = await self._create_direct_connection(req, traces, timeout)
  File "/Users/ilyasleptsov/Library/Caches/pypoetry/virtualenvs/dex-gainers-losers-bKWl_PyR-py3.9/lib/python3.9/site-packages/aiohttp/connector.py", line 1169, in _create_direct_connection
    raise ClientConnectorError(req.connection_key, exc) from exc
aiohttp.client_exceptions.ClientConnectorError: Cannot connect to host gateway-us-east1-b.discord.gg:443 ssl:default [nodename nor servname provided, or not known]
[2023.08.08 12:23:34] E Task exception was never retrieved
future: <Task finished name='Task-1' coro=<make_schedule() done, defined at /Users/ilyasleptsov/Desktop/python/dex_gainers_losers/send_top_gainers_losers.py:8> exception=TypeError("__init__() got an unexpected keyword argument 'hours'")>
Traceback (most recent call last):
  File "/Users/ilyasleptsov/Desktop/python/dex_gainers_losers/send_top_gainers_losers.py", line 10, in make_schedule
    scheduler.add_job(send_daily_stats, 'cron', hours="22")
  File "/Users/ilyasleptsov/Library/Caches/pypoetry/virtualenvs/dex-gainers-losers-bKWl_PyR-py3.9/lib/python3.9/site-packages/apscheduler/schedulers/base.py", line 424, in add_job
    'trigger': self._create_trigger(trigger, trigger_args),
  File "/Users/ilyasleptsov/Library/Caches/pypoetry/virtualenvs/dex-gainers-losers-bKWl_PyR-py3.9/lib/python3.9/site-packages/apscheduler/schedulers/base.py", line 925, in _create_trigger
    return self._create_plugin_instance('trigger', trigger, trigger_args)
  File "/Users/ilyasleptsov/Library/Caches/pypoetry/virtualenvs/dex-gainers-losers-bKWl_PyR-py3.9/lib/python3.9/site-packages/apscheduler/schedulers/base.py", line 910, in _create_plugin_instance
    return plugin_cls(**constructor_kwargs)
TypeError: __init__() got an unexpected keyword argument 'hours'
[2023.08.08 12:23:34] W PyNaCl is not installed, voice will NOT be supported
[2023.08.08 12:23:56] E Task exception was never retrieved
future: <Task finished name='Task-1' coro=<make_schedule() done, defined at /Users/ilyasleptsov/Desktop/python/dex_gainers_losers/send_top_gainers_losers.py:8> exception=TypeError("__init__() got an unexpected keyword argument 'hours'")>
Traceback (most recent call last):
  File "/Users/ilyasleptsov/Desktop/python/dex_gainers_losers/send_top_gainers_losers.py", line 10, in make_schedule
    scheduler.add_job(send_daily_stats, 'cron', hours="22")
  File "/Users/ilyasleptsov/Library/Caches/pypoetry/virtualenvs/dex-gainers-losers-bKWl_PyR-py3.9/lib/python3.9/site-packages/apscheduler/schedulers/base.py", line 424, in add_job
    'trigger': self._create_trigger(trigger, trigger_args),
  File "/Users/ilyasleptsov/Library/Caches/pypoetry/virtualenvs/dex-gainers-losers-bKWl_PyR-py3.9/lib/python3.9/site-packages/apscheduler/schedulers/base.py", line 925, in _create_trigger
    return self._create_plugin_instance('trigger', trigger, trigger_args)
  File "/Users/ilyasleptsov/Library/Caches/pypoetry/virtualenvs/dex-gainers-losers-bKWl_PyR-py3.9/lib/python3.9/site-packages/apscheduler/schedulers/base.py", line 910, in _create_plugin_instance
    return plugin_cls(**constructor_kwargs)
TypeError: __init__() got an unexpected keyword argument 'hours'
[2023.08.08 12:23:56] W PyNaCl is not installed, voice will NOT be supported
[2023.08.08 18:49:49] W PyNaCl is not installed, voice will NOT be supported
[2023.08.08 18:50:08] E Ignoring exception in on_message
Traceback (most recent call last):
  File "/Users/ilyasleptsov/Library/Caches/pypoetry/virtualenvs/dex-gainers-losers-bKWl_PyR-py3.9/lib/python3.9/site-packages/discord/client.py", line 441, in _run_event
    await coro(*args, **kwargs)
  File "/Users/ilyasleptsov/Desktop/python/dex_gainers_losers/discord_worker.py", line 23, in on_message
    await message.channel.send(stats_message)
  File "/Users/ilyasleptsov/Library/Caches/pypoetry/virtualenvs/dex-gainers-losers-bKWl_PyR-py3.9/lib/python3.9/site-packages/discord/abc.py", line 1562, in send
    data = await state.http.send_message(channel.id, params=params)
  File "/Users/ilyasleptsov/Library/Caches/pypoetry/virtualenvs/dex-gainers-losers-bKWl_PyR-py3.9/lib/python3.9/site-packages/discord/http.py", line 745, in request
    raise HTTPException(response, data)
discord.errors.HTTPException: 400 Bad Request (error code: 50035): Invalid Form Body
In content: Must be 2000 or fewer in length.
[2023.08.08 18:53:33] W PyNaCl is not installed, voice will NOT be supported
[2023.08.08 18:55:29] E Ignoring exception in on_message
Traceback (most recent call last):
  File "/Users/ilyasleptsov/Library/Caches/pypoetry/virtualenvs/dex-gainers-losers-bKWl_PyR-py3.9/lib/python3.9/site-packages/discord/client.py", line 441, in _run_event
    await coro(*args, **kwargs)
  File "/Users/ilyasleptsov/Desktop/python/dex_gainers_losers/discord_worker.py", line 23, in on_message
    await message.channel.send(stats_message)
  File "/Users/ilyasleptsov/Library/Caches/pypoetry/virtualenvs/dex-gainers-losers-bKWl_PyR-py3.9/lib/python3.9/site-packages/discord/abc.py", line 1562, in send
    data = await state.http.send_message(channel.id, params=params)
  File "/Users/ilyasleptsov/Library/Caches/pypoetry/virtualenvs/dex-gainers-losers-bKWl_PyR-py3.9/lib/python3.9/site-packages/discord/http.py", line 745, in request
    raise HTTPException(response, data)
discord.errors.HTTPException: 400 Bad Request (error code: 50035): Invalid Form Body
In content: Must be 2000 or fewer in length.
[2023.08.08 19:02:33] W PyNaCl is not installed, voice will NOT be supported
[2023.08.08 19:14:47] W PyNaCl is not installed, voice will NOT be supported
[2023.08.08 19:18:12] W PyNaCl is not installed, voice will NOT be supported
[2023.08.08 19:22:39] W PyNaCl is not installed, voice will NOT be supported
[2023.08.08 19:38:54] W PyNaCl is not installed, voice will NOT be supported
[2023.08.08 19:41:33] W PyNaCl is not installed, voice will NOT be supported
[2023.08.08 19:44:14] I Adding job tentatively -- it will be properly scheduled when the scheduler starts
[2023.08.08 19:44:14] I Added job "send_daily_stats" to job store "default"
[2023.08.08 19:44:14] I Scheduler started
[2023.08.08 19:44:14] W PyNaCl is not installed, voice will NOT be supported
[2023.08.08 19:44:14] I logging in using static token
[2023.08.08 19:44:16] I Shard ID None has connected to Gateway (Session ID: e103163cb82ce01ca890a4fa5ac4217a).
[2023.08.08 19:44:55] I Adding job tentatively -- it will be properly scheduled when the scheduler starts
[2023.08.08 19:44:55] I Added job "send_daily_stats" to job store "default"
[2023.08.08 19:44:55] I Scheduler started
[2023.08.08 19:44:55] W PyNaCl is not installed, voice will NOT be supported
[2023.08.08 19:44:55] I logging in using static token
[2023.08.08 19:44:58] I Shard ID None has connected to Gateway (Session ID: 1179042c3690e5ba504b926f1055e3b1).
[2023.08.08 19:45:32] I Adding job tentatively -- it will be properly scheduled when the scheduler starts
[2023.08.08 19:45:32] I Added job "send_daily_stats" to job store "default"
[2023.08.08 19:45:32] I Scheduler started
[2023.08.08 19:45:32] W PyNaCl is not installed, voice will NOT be supported
[2023.08.08 19:45:32] I logging in using static token
[2023.08.08 19:45:35] I Shard ID None has connected to Gateway (Session ID: ca49a0949a6fcac869ce3253de3006a5).
[2023.08.08 19:46:32] I Running job "send_daily_stats (trigger: interval[0:01:00], next run at: 2023-08-08 19:47:32 EEST)" (scheduled at 2023-08-08 19:46:32.187249+03:00)
[2023.08.08 19:46:37] I HTTP Request: POST https://api.telegram.org/bot6456238733:AAGRsdlpkB_edeA3becFwDdswd-VjrM76-E/sendMessage "HTTP/1.1 200 OK"
[2023.08.08 19:46:37] I Job "send_daily_stats (trigger: interval[0:01:00], next run at: 2023-08-08 19:47:32 EEST)" executed successfully
[2023.08.08 19:47:41] I Adding job tentatively -- it will be properly scheduled when the scheduler starts
[2023.08.08 19:47:41] I Added job "send_daily_stats" to job store "default"
[2023.08.08 19:47:41] I Scheduler started
[2023.08.08 19:47:41] W PyNaCl is not installed, voice will NOT be supported
[2023.08.08 19:47:41] I logging in using static token
[2023.08.08 19:47:44] I Shard ID None has connected to Gateway (Session ID: fe58fedc22345f18fd42c96994087202).
[2023.08.08 19:48:41] I Running job "send_daily_stats (trigger: interval[0:01:00], next run at: 2023-08-08 19:49:41 EEST)" (scheduled at 2023-08-08 19:48:41.897631+03:00)
[2023.08.08 19:48:47] I HTTP Request: POST https://api.telegram.org/bot6456238733:AAGRsdlpkB_edeA3becFwDdswd-VjrM76-E/sendMessage "HTTP/1.1 200 OK"
[2023.08.08 19:48:47] I Job "send_daily_stats (trigger: interval[0:01:00], next run at: 2023-08-08 19:49:41 EEST)" executed successfully
[2023.08.08 19:49:08] E Task exception was never retrieved
future: <Task finished name='Task-1' coro=<make_schedule() done, defined at /Users/ilyasleptsov/Desktop/python/dex_gainers_losers/send_top_gainers_losers.py:8> exception=TypeError("__init__() got an unexpected keyword argument 'hours'")>
Traceback (most recent call last):
  File "/Users/ilyasleptsov/Desktop/python/dex_gainers_losers/send_top_gainers_losers.py", line 10, in make_schedule
    scheduler.add_job(send_daily_stats, 'cron', hours="22")
  File "/Users/ilyasleptsov/Library/Caches/pypoetry/virtualenvs/dex-gainers-losers-bKWl_PyR-py3.9/lib/python3.9/site-packages/apscheduler/schedulers/base.py", line 424, in add_job
    'trigger': self._create_trigger(trigger, trigger_args),
  File "/Users/ilyasleptsov/Library/Caches/pypoetry/virtualenvs/dex-gainers-losers-bKWl_PyR-py3.9/lib/python3.9/site-packages/apscheduler/schedulers/base.py", line 925, in _create_trigger
    return self._create_plugin_instance('trigger', trigger, trigger_args)
  File "/Users/ilyasleptsov/Library/Caches/pypoetry/virtualenvs/dex-gainers-losers-bKWl_PyR-py3.9/lib/python3.9/site-packages/apscheduler/schedulers/base.py", line 910, in _create_plugin_instance
    return plugin_cls(**constructor_kwargs)
TypeError: __init__() got an unexpected keyword argument 'hours'
[2023.08.08 19:49:08] W PyNaCl is not installed, voice will NOT be supported
[2023.08.08 19:49:08] I logging in using static token
[2023.08.08 19:49:10] I Shard ID None has connected to Gateway (Session ID: 1f19a35b0af87eef4a52a1bd445ceeb5).
[2023.08.08 20:08:17] E Task exception was never retrieved
future: <Task finished name='Task-1' coro=<make_schedule() done, defined at /Users/ilyasleptsov/Desktop/python/dex_gainers_losers/send_top_gainers_losers.py:8> exception=TypeError("__init__() got an unexpected keyword argument 'hours'")>
Traceback (most recent call last):
  File "/Users/ilyasleptsov/Desktop/python/dex_gainers_losers/send_top_gainers_losers.py", line 10, in make_schedule
    scheduler.add_job(send_daily_stats, 'cron', hours="22")
  File "/Users/ilyasleptsov/Library/Caches/pypoetry/virtualenvs/dex-gainers-losers-bKWl_PyR-py3.9/lib/python3.9/site-packages/apscheduler/schedulers/base.py", line 424, in add_job
    'trigger': self._create_trigger(trigger, trigger_args),
  File "/Users/ilyasleptsov/Library/Caches/pypoetry/virtualenvs/dex-gainers-losers-bKWl_PyR-py3.9/lib/python3.9/site-packages/apscheduler/schedulers/base.py", line 925, in _create_trigger
    return self._create_plugin_instance('trigger', trigger, trigger_args)
  File "/Users/ilyasleptsov/Library/Caches/pypoetry/virtualenvs/dex-gainers-losers-bKWl_PyR-py3.9/lib/python3.9/site-packages/apscheduler/schedulers/base.py", line 910, in _create_plugin_instance
    return plugin_cls(**constructor_kwargs)
TypeError: __init__() got an unexpected keyword argument 'hours'
[2023.08.08 20:08:17] W PyNaCl is not installed, voice will NOT be supported
[2023.08.08 20:08:17] I logging in using static token
[2023.08.08 20:08:20] I Shard ID None has connected to Gateway (Session ID: 283690b5b3726e168d8fc1febef63109).
[2023.08.08 20:09:54] I Adding job tentatively -- it will be properly scheduled when the scheduler starts
[2023.08.08 20:09:54] I Added job "send_daily_stats" to job store "default"
[2023.08.08 20:09:54] I Scheduler started
[2023.08.08 20:09:54] W PyNaCl is not installed, voice will NOT be supported
[2023.08.08 20:09:54] I logging in using static token
[2023.08.08 20:09:57] I Shard ID None has connected to Gateway (Session ID: e5c976d7d5777e458baf53529c1b886f).
[2023.08.08 20:10:54] I Running job "send_daily_stats (trigger: interval[0:01:00], next run at: 2023-08-08 20:11:54 EEST)" (scheduled at 2023-08-08 20:10:54.883141+03:00)
[2023.08.08 20:11:00] I HTTP Request: POST https://api.telegram.org/bot6456238733:AAGRsdlpkB_edeA3becFwDdswd-VjrM76-E/sendMessage "HTTP/1.1 200 OK"
[2023.08.08 20:11:00] I Job "send_daily_stats (trigger: interval[0:01:00], next run at: 2023-08-08 20:11:54 EEST)" executed successfully
[2023.08.08 20:14:46] I Adding job tentatively -- it will be properly scheduled when the scheduler starts
[2023.08.08 20:14:46] I Added job "send_daily_stats" to job store "default"
[2023.08.08 20:14:46] I Scheduler started
[2023.08.08 20:14:46] W PyNaCl is not installed, voice will NOT be supported
[2023.08.08 20:14:46] I logging in using static token
[2023.08.08 20:14:49] I Shard ID None has connected to Gateway (Session ID: 62bcd3eb8387cffcc6febc30ae167267).
[2023.08.08 20:15:46] I Running job "send_daily_stats (trigger: interval[0:01:00], next run at: 2023-08-08 20:16:46 EEST)" (scheduled at 2023-08-08 20:15:46.960962+03:00)
[2023.08.08 20:15:52] I HTTP Request: POST https://api.telegram.org/bot6456238733:AAGRsdlpkB_edeA3becFwDdswd-VjrM76-E/sendMessage "HTTP/1.1 200 OK"
[2023.08.08 20:15:52] I Job "send_daily_stats (trigger: interval[0:01:00], next run at: 2023-08-08 20:16:46 EEST)" executed successfully
